Workbook

Sheet Dashboard
B2: Recommendarr — Human-Read Audit Checklist
B3: Organic execution order · every .py + .md · verify each file does what it claims
B5: OVERALL PROGRESS
B6: Total files to audit | C6: =COUNTA(Checklist!$E$2:$E$709) -> 708
B7: ① Human-read complete | C7: =COUNTIF(Checklist!$J$2:$J$709,"✔ Pass")+COUNTIF(Checklist!$J$2:$J$709,"⚠ Concern")+COUNTIF(Checklist!$J$2:$J$709,"✖ Fail")+COUNTIF(Checklist!$J$2:$J$709,"— N/A") -> 0
B8: └ % reviewed | C8: =IF(C6=0,0,C7/C6) -> 0
B9: ✔ Passed clean | C9: =COUNTIF(Checklist!$J$2:$J$709,"✔ Pass") -> 0
B10: ⚠ Concerns flagged | C10: =COUNTIF(Checklist!$J$2:$J$709,"⚠ Concern") -> 0
B11: ✖ Failed read | C11: =COUNTIF(Checklist!$J$2:$J$709,"✖ Fail") -> 0
B12: ② Confirmed does-what-it-says | C12: =COUNTIF(Checklist!$K$2:$K$709,"Yes") -> 0
B13: └ ⚠ Partial / ✖ No | C13: =COUNTIF(Checklist!$K$2:$K$709,"Partial")+COUNTIF(Checklist!$K$2:$K$709,"No") -> 0
B14: ③ .md docs accurate | C14: =COUNTIF(Checklist!$L$2:$L$709,"Yes") -> 0
B15: └ Stale / Wrong .md | C15: =COUNTIF(Checklist!$L$2:$L$709,"Stale")+COUNTIF(Checklist!$L$2:$L$709,"Wrong") -> 0
B17: PROGRESS BY EXECUTION STAGE
B18: Stage (organic run order) | C18: Files | D18: Reviewed | E18: % Done | F18: Concerns | G18: Does-NOT | H18: Sec-flagged
B19: 00 · Entry · main.py | C19: =COUNTIF(Checklist!$B$2:$B$709,"Entry · main.py") -> 1 | D19: =COUNTIFS(Checklist!$B$2:$B$709,"Entry · main.py",Checklist!$J$2:$J$709,"<>") -> 0 | E19: =IF(C19=0,0,D19/C19) -> 0 | F19: =COUNTIFS(Checklist!$B$2:$B$709,"Entry · main.py",Checklist!$J$2:$J$709,"⚠ Concern") -> 0 | G19: =COUNTIFS(Checklist!$B$2:$B$709,"Entry · main.py",Checklist!$K$2:$K$709,"No") -> 0 | H19: =COUNTIFS(Checklist!$B$2:$B$709,"Entry · main.py",Checklist!$G$2:$G$709,"?*") -> 1
B20: 00 · Entry · onboarding | C20: =COUNTIF(Checklist!$B$2:$B$709,"Entry · onboarding") -> 19 | D20: =COUNTIFS(Checklist!$B$2:$B$709,"Entry · onboarding",Checklist!$J$2:$J$709,"<>") -> 0 | E20: =IF(C20=0,0,D20/C20) -> 0 | F20: =COUNTIFS(Checklist!$B$2:$B$709,"Entry · onboarding",Checklist!$J$2:$J$709,"⚠ Concern") -> 0 | G20: =COUNTIFS(Checklist!$B$2:$B$709,"Entry · onboarding",Checklist!$K$2:$K$709,"No") -> 0 | H20: =COUNTIFS(Checklist!$B$2:$B$709,"Entry · onboarding",Checklist!$G$2:$G$709,"?*") -> 12
B21: 00 · Entry · config + secrets | C21: =COUNTIF(Checklist!$B$2:$B$709,"Entry · config + secrets") -> 10 | D21: =COUNTIFS(Checklist!$B$2:$B$709,"Entry · config + secrets",Checklist!$J$2:$J$709,"<>") -> 0 | E21: =IF(C21=0,0,D21/C21) -> 0 | F21: =COUNTIFS(Checklist!$B$2:$B$709,"Entry · config + secrets",Checklist!$J$2:$J$709,"⚠ Concern") -> 0 | G21: =COUNTIFS(Checklist!$B$2:$B$709,"Entry · config + secrets",Checklist!$K$2:$K$709,"No") -> 0 | H21: =COUNTIFS(Checklist!$B$2:$B$709,"Entry · config + secrets",Checklist!$G$2:$G$709,"?*") -> 6
B22: 00 · Entry · auth validation | C22: =COUNTIF(Checklist!$B$2:$B$709,"Entry · auth validation") -> 2 | D22: =COUNTIFS(Checklist!$B$2:$B$709,"Entry · auth validation",Checklist!$J$2:$J$709,"<>") -> 0 | E22: =IF(C22=0,0,D22/C22) -> 0 | F22: =COUNTIFS(Checklist!$B$2:$B$709,"Entry · auth validation",Checklist!$J$2:$J$709,"⚠ Concern") -> 0 | G22: =COUNTIFS(Checklist!$B$2:$B$709,"Entry · auth validation",Checklist!$K$2:$K$709,"No") -> 0 | H22: =COUNTIFS(Checklist!$B$2:$B$709,"Entry · auth validation",Checklist!$G$2:$G$709,"?*") -> 1
B23: 00 · Entry · logging | C23: =COUNTIF(Checklist!$B$2:$B$709,"Entry · logging") -> 2 | D23: =COUNTIFS(Checklist!$B$2:$B$709,"Entry · logging",Checklist!$J$2:$J$709,"<>") -> 0 | E23: =IF(C23=0,0,D23/C23) -> 0 | F23: =COUNTIFS(Checklist!$B$2:$B$709,"Entry · logging",Checklist!$J$2:$J$709,"⚠ Concern") -> 0 | G23: =COUNTIFS(Checklist!$B$2:$B$709,"Entry · logging",Checklist!$K$2:$K$709,"No") -> 0 | H23: =COUNTIFS(Checklist!$B$2:$B$709,"Entry · logging",Checklist!$G$2:$G$709,"?*") -> 1
B24: 00 · Entry · setup scripts | C24: =COUNTIF(Checklist!$B$2:$B$709,"Entry · setup scripts") -> 4 | D24: =COUNTIFS(Checklist!$B$2:$B$709,"Entry · setup scripts",Checklist!$J$2:$J$709,"<>") -> 0 | E24: =IF(C24=0,0,D24/C24) -> 0 | F24: =COUNTIFS(Checklist!$B$2:$B$709,"Entry · setup scripts",Checklist!$J$2:$J$709,"⚠ Concern") -> 0 | G24: =COUNTIFS(Checklist!$B$2:$B$709,"Entry · setup scripts",Checklist!$K$2:$K$709,"No") -> 0 | H24: =COUNTIFS(Checklist!$B$2:$B$709,"Entry · setup scripts",Checklist!$G$2:$G$709,"?*") -> 4
B25: 00 · Entry · git/CI hooks | C25: =COUNTIF(Checklist!$B$2:$B$709,"Entry · git/CI hooks") -> 3 | D25: =COUNTIFS(Checklist!$B$2:$B$709,"Entry · git/CI hooks",Checklist!$J$2:$J$709,"<>") -> 0 | E25: =IF(C25=0,0,D25/C25) -> 0 | F25: =COUNTIFS(Checklist!$B$2:$B$709,"Entry · git/CI hooks",Checklist!$J$2:$J$709,"⚠ Concern") -> 0 | G25: =COUNTIFS(Checklist!$B$2:$B$709,"Entry · git/CI hooks",Checklist!$K$2:$K$709,"No") -> 0 | H25: =COUNTIFS(Checklist!$B$2:$B$709,"Entry · git/CI hooks",Checklist!$G$2:$G$709,"?*") -> 3
B26: 01 · Daemon · supervisor/paths | C26: =COUNTIF(Checklist!$B$2:$B$709,"Daemon · supervisor/paths") -> 3 | D26: =COUNTIFS(Checklist!$B$2:$B$709,"Daemon · supervisor/paths",Checklist!$J$2:$J$709,"<>") -> 0 | E26: =IF(C26=0,0,D26/C26) -> 0 | F26: =COUNTIFS(Checklist!$B$2:$B$709,"Daemon · supervisor/paths",Checklist!$J$2:$J$709,"⚠ Concern") -> 0 | G26: =COUNTIFS(Checklist!$B$2:$B$709,"Daemon · supervisor/paths",Checklist!$K$2:$K$709,"No") -> 0 | H26: =COUNTIFS(Checklist!$B$2:$B$709,"Daemon · supervisor/paths",Checklist!$G$2:$G$709,"?*") -> 2
B27: 01 · Daemon · enrich loop | C27: =COUNTIF(Checklist!$B$2:$B$709,"Daemon · enrich loop") -> 1 | D27: =COUNTIFS(Checklist!$B$2:$B$709,"Daemon · enrich loop",Checklist!$J$2:$J$709,"<>") -> 0 | E27: =IF(C27=0,0,D27/C27) -> 0 | F27: =COUNTIFS(Checklist!$B$2:$B$709,"Daemon · enrich loop",Checklist!$J$2:$J$709,"⚠ Concern") -> 0 | G27: =COUNTIFS(Checklist!$B$2:$B$709,"Daemon · enrich loop",Checklist!$K$2:$K$709,"No") -> 0 | H27: =COUNTIFS(Checklist!$B$2:$B$709,"Daemon · enrich loop",Checklist!$G$2:$G$709,"?*") -> 1
B28: 02 · Scripts · package init | C28: =COUNTIF(Checklist!$B$2:$B$709,"Scripts · package init") -> 3 | D28: =COUNTIFS(Checklist!$B$2:$B$709,"Scripts · package init",Checklist!$J$2:$J$709,"<>") -> 0 | E28: =IF(C28=0,0,D28/C28) -> 0 | F28: =COUNTIFS(Checklist!$B$2:$B$709,"Scripts · package init",Checklist!$J$2:$J$709,"⚠ Concern") -> 0 | G28: =COUNTIFS(Checklist!$B$2:$B$709,"Scripts · package init",Checklist!$K$2:$K$709,"No") -> 0 | H28: =COUNTIFS(Checklist!$B$2:$B$709,"Scripts · package init",Checklist!$G$2:$G$709,"?*") -> 0
B29: 02 · Factories · core plumbing | C29: =COUNTIF(Checklist!$B$2:$B$709,"Factories · core plumbing") -> 39 | D29: =COUNTIFS(Checklist!$B$2:$B$709,"Factories · core plumbing",Checklist!$J$2:$J$709,"<>") -> 0 | E29: =IF(C29=0,0,D29/C29) -> 0 | F29: =COUNTIFS(Checklist!$B$2:$B$709,"Factories · core plumbing",Checklist!$J$2:$J$709,"⚠ Concern") -> 0 | G29: =COUNTIFS(Checklist!$B$2:$B$709,"Factories · core plumbing",Checklist!$K$2:$K$709,"No") -> 0 | H29: =COUNTIFS(Checklist!$B$2:$B$709,"Factories · core plumbing",Checklist!$G$2:$G$709,"?*") -> 8
B30: 03 · Tautulli | C30: =COUNTIF(Checklist!$B$2:$B$709,"Tautulli") -> 27 | D30: =COUNTIFS(Checklist!$B$2:$B$709,"Tautulli",Checklist!$J$2:$J$709,"<>") -> 0 | E30: =IF(C30=0,0,D30/C30) -> 0 | F30: =COUNTIFS(Checklist!$B$2:$B$709,"Tautulli",Checklist!$J$2:$J$709,"⚠ Concern") -> 0 | G30: =COUNTIFS(Checklist!$B$2:$B$709,"Tautulli",Checklist!$K$2:$K$709,"No") -> 0 | H30: =COUNTIFS(Checklist!$B$2:$B$709,"Tautulli",Checklist!$G$2:$G$709,"?*") -> 2
B31: 04 · Trakt | C31: =COUNTIF(Checklist!$B$2:$B$709,"Trakt") -> 51 | D31: =COUNTIFS(Checklist!$B$2:$B$709,"Trakt",Checklist!$J$2:$J$709,"<>") -> 0 | E31: =IF(C31=0,0,D31/C31) -> 0 | F31: =COUNTIFS(Checklist!$B$2:$B$709,"Trakt",Checklist!$J$2:$J$709,"⚠ Concern") -> 0 | G31: =COUNTIFS(Checklist!$B$2:$B$709,"Trakt",Checklist!$K$2:$K$709,"No") -> 0 | H31: =COUNTIFS(Checklist!$B$2:$B$709,"Trakt",Checklist!$G$2:$G$709,"?*") -> 9
B32: 05 · MAL (anime) | C32: =COUNTIF(Checklist!$B$2:$B$709,"MAL (anime)") -> 6 | D32: =COUNTIFS(Checklist!$B$2:$B$709,"MAL (anime)",Checklist!$J$2:$J$709,"<>") -> 0 | E32: =IF(C32=0,0,D32/C32) -> 0 | F32: =COUNTIFS(Checklist!$B$2:$B$709,"MAL (anime)",Checklist!$J$2:$J$709,"⚠ Concern") -> 0 | G32: =COUNTIFS(Checklist!$B$2:$B$709,"MAL (anime)",Checklist!$K$2:$K$709,"No") -> 0 | H32: =COUNTIFS(Checklist!$B$2:$B$709,"MAL (anime)",Checklist!$G$2:$G$709,"?*") -> 2
B33: 06 · Sonarr | C33: =COUNTIF(Checklist!$B$2:$B$709,"Sonarr") -> 226 | D33: =COUNTIFS(Checklist!$B$2:$B$709,"Sonarr",Checklist!$J$2:$J$709,"<>") -> 0 | E33: =IF(C33=0,0,D33/C33) -> 0 | F33: =COUNTIFS(Checklist!$B$2:$B$709,"Sonarr",Checklist!$J$2:$J$709,"⚠ Concern") -> 0 | G33: =COUNTIFS(Checklist!$B$2:$B$709,"Sonarr",Checklist!$K$2:$K$709,"No") -> 0 | H33: =COUNTIFS(Checklist!$B$2:$B$709,"Sonarr",Checklist!$G$2:$G$709,"?*") -> 35
B34: 07 · Radarr | C34: =COUNTIF(Checklist!$B$2:$B$709,"Radarr") -> 129 | D34: =COUNTIFS(Checklist!$B$2:$B$709,"Radarr",Checklist!$J$2:$J$709,"<>") -> 0 | E34: =IF(C34=0,0,D34/C34) -> 0 | F34: =COUNTIFS(Checklist!$B$2:$B$709,"Radarr",Checklist!$J$2:$J$709,"⚠ Concern") -> 0 | G34: =COUNTIFS(Checklist!$B$2:$B$709,"Radarr",Checklist!$K$2:$K$709,"No") -> 0 | H34: =COUNTIFS(Checklist!$B$2:$B$709,"Radarr",Checklist!$G$2:$G$709,"?*") -> 13
B35: 08 · ML brain | C35: =COUNTIF(Checklist!$B$2:$B$709,"ML brain") -> 99 | D35: =COUNTIFS(Checklist!$B$2:$B$709,"ML brain",Checklist!$J$2:$J$709,"<>") -> 0 | E35: =IF(C35=0,0,D35/C35) -> 0 | F35: =COUNTIFS(Checklist!$B$2:$B$709,"ML brain",Checklist!$J$2:$J$709,"⚠ Concern") -> 0 | G35: =COUNTIFS(Checklist!$B$2:$B$709,"ML brain",Checklist!$K$2:$K$709,"No") -> 0 | H35: =COUNTIFS(Checklist!$B$2:$B$709,"ML brain",Checklist!$G$2:$G$709,"?*") -> 8
B36: 09 · Space coordinator | C36: =COUNTIF(Checklist!$B$2:$B$709,"Space coordinator") -> 4 | D36: =COUNTIFS(Checklist!$B$2:$B$709,"Space coordinator",Checklist!$J$2:$J$709,"<>") -> 0 | E36: =IF(C36=0,0,D36/C36) -> 0 | F36: =COUNTIFS(Checklist!$B$2:$B$709,"Space coordinator",Checklist!$J$2:$J$709,"⚠ Concern") -> 0 | G36: =COUNTIFS(Checklist!$B$2:$B$709,"Space coordinator",Checklist!$K$2:$K$709,"No") -> 0 | H36: =COUNTIFS(Checklist!$B$2:$B$709,"Space coordinator",Checklist!$G$2:$G$709,"?*") -> 1
B37: 10 · Acquisition | C37: =COUNTIF(Checklist!$B$2:$B$709,"Acquisition") -> 8 | D37: =COUNTIFS(Checklist!$B$2:$B$709,"Acquisition",Checklist!$J$2:$J$709,"<>") -> 0 | E37: =IF(C37=0,0,D37/C37) -> 0 | F37: =COUNTIFS(Checklist!$B$2:$B$709,"Acquisition",Checklist!$J$2:$J$709,"⚠ Concern") -> 0 | G37: =COUNTIFS(Checklist!$B$2:$B$709,"Acquisition",Checklist!$K$2:$K$709,"No") -> 0 | H37: =COUNTIFS(Checklist!$B$2:$B$709,"Acquisition",Checklist!$G$2:$G$709,"?*") -> 1
B38: 10 · Calendar | C38: =COUNTIF(Checklist!$B$2:$B$709,"Calendar") -> 2 | D38: =COUNTIFS(Checklist!$B$2:$B$709,"Calendar",Checklist!$J$2:$J$709,"<>") -> 0 | E38: =IF(C38=0,0,D38/C38) -> 0 | F38: =COUNTIFS(Checklist!$B$2:$B$709,"Calendar",Checklist!$J$2:$J$709,"⚠ Concern") -> 0 | G38: =COUNTIFS(Checklist!$B$2:$B$709,"Calendar",Checklist!$K$2:$K$709,"No") -> 0 | H38: =COUNTIFS(Checklist!$B$2:$B$709,"Calendar",Checklist!$G$2:$G$709,"?*") -> 0
B39: 10 · Services · package init | C39: =COUNTIF(Checklist!$B$2:$B$709,"Services · package init") -> 1 | D39: =COUNTIFS(Checklist!$B$2:$B$709,"Services · package init",Checklist!$J$2:$J$709,"<>") -> 0 | E39: =IF(C39=0,0,D39/C39) -> 0 | F39: =COUNTIFS(Checklist!$B$2:$B$709,"Services · package init",Checklist!$J$2:$J$709,"⚠ Concern") -> 0 | G39: =COUNTIFS(Checklist!$B$2:$B$709,"Services · package init",Checklist!$K$2:$K$709,"No") -> 0 | H39: =COUNTIFS(Checklist!$B$2:$B$709,"Services · package init",Checklist!$G$2:$G$709,"?*") -> 0
B40: 10 · Renamer | C40: =COUNTIF(Checklist!$B$2:$B$709,"Renamer") -> 1 | D40: =COUNTIFS(Checklist!$B$2:$B$709,"Renamer",Checklist!$J$2:$J$709,"<>") -> 0 | E40: =IF(C40=0,0,D40/C40) -> 0 | F40: =COUNTIFS(Checklist!$B$2:$B$709,"Renamer",Checklist!$J$2:$J$709,"⚠ Concern") -> 0 | G40: =COUNTIFS(Checklist!$B$2:$B$709,"Renamer",Checklist!$K$2:$K$709,"No") -> 0 | H40: =COUNTIFS(Checklist!$B$2:$B$709,"Renamer",Checklist!$G$2:$G$709,"?*") -> 1
B41: 10 · Writeback | C41: =COUNTIF(Checklist!$B$2:$B$709,"Writeback") -> 6 | D41: =COUNTIFS(Checklist!$B$2:$B$709,"Writeback",Checklist!$J$2:$J$709,"<>") -> 0 | E41: =IF(C41=0,0,D41/C41) -> 0 | F41: =COUNTIFS(Checklist!$B$2:$B$709,"Writeback",Checklist!$J$2:$J$709,"⚠ Concern") -> 0 | G41: =COUNTIFS(Checklist!$B$2:$B$709,"Writeback",Checklist!$K$2:$K$709,"No") -> 0 | H41: =COUNTIFS(Checklist!$B$2:$B$709,"Writeback",Checklist!$G$2:$G$709,"?*") -> 0
B42: 11 · Notifications | C42: =COUNTIF(Checklist!$B$2:$B$709,"Notifications") -> 3 | D42: =COUNTIFS(Checklist!$B$2:$B$709,"Notifications",Checklist!$J$2:$J$709,"<>") -> 0 | E42: =IF(C42=0,0,D42/C42) -> 0 | F42: =COUNTIFS(Checklist!$B$2:$B$709,"Notifications",Checklist!$J$2:$J$709,"⚠ Concern") -> 0 | G42: =COUNTIFS(Checklist!$B$2:$B$709,"Notifications",Checklist!$K$2:$K$709,"No") -> 0 | H42: =COUNTIFS(Checklist!$B$2:$B$709,"Notifications",Checklist!$G$2:$G$709,"?*") -> 2
B43: 11 · Dry-run ledger | C43: =COUNTIF(Checklist!$B$2:$B$709,"Dry-run ledger") -> 1 | D43: =COUNTIFS(Checklist!$B$2:$B$709,"Dry-run ledger",Checklist!$J$2:$J$709,"<>") -> 0 | E43: =IF(C43=0,0,D43/C43) -> 0 | F43: =COUNTIFS(Checklist!$B$2:$B$709,"Dry-run ledger",Checklist!$J$2:$J$709,"⚠ Concern") -> 0 | G43: =COUNTIFS(Checklist!$B$2:$B$709,"Dry-run ledger",Checklist!$K$2:$K$709,"No") -> 0 | H43: =COUNTIFS(Checklist!$B$2:$B$709,"Dry-run ledger",Checklist!$G$2:$G$709,"?*") -> 0
...

Sheet Checklist
A1: # | B1: Stage | C1: When / Run-phase | D1: Component | E1: File (path from repo root) | F1: Type | G1: Sec* | H1: Purpose — what it CLAIMS to do | I1: Top defs (classes · functions) | J1: ① Human-read? | K1: ② Does what it says? | L1: ③ .md accurate? | M1: Reviewer | N1: Date | O1: Notes / issues found | P1: LOC | Q1: Paired .md | R1: ▶
A2: 1 | B2: Entry · main.py | C2: Cold start — process entry | D2: main.py | E2: scripts/main.py | F2: PY | G2: NET DEL SEC FS | I2: Main | P2: 551 | Q2: scripts/main.md | R2: ▶
A3: 2 | B3: Entry · onboarding | C3: Cold start — first-run setup | D3: onboarding | E3: scripts/managers/factories/onboarding/__init__.py | F3: PY | G3: NET SEC | H3: OnboardingManager — first-run / full-setup wizard for Recommendarr. ================================================================================ Establishes an entire setup in one flow: root folders, the number of Sonarr/Radarr sessions + their API keys, Trakt OAuth (incl. token generation), Tautulli, Plex, TVDB, MAL, genres, free-space limit, dry-run and Discord notifications. Secrets are per | I3: OnboardingManager | P3: 177 | Q3: —
A4: 3 | B4: Entry · onboarding | C4: Cold start — first-run setup | D4: onboarding | E4: scripts/managers/factories/onboarding/env_map.py | F4: PY | G4: NET DEL SEC | H4: env_map.py — the headless / Docker / unraid environment-variable contract. ================================================================================ Every config leaf maps to a ``RECOMMENDARR_*`` environment variable using the SAME convention the SecretStore already uses for secrets (``secret_store.env_name`` — e.g. ``trakt.client_secret`` -> ``RECOMMENDARR_TRAKT_CLIENT_SECRET``). Onboardin | I4: env_for, get_env, split_list, instance_names | P4: 169 | Q4: —
A5: 4 | B5: Entry · onboarding | C5: Cold start — first-run setup | D5: onboarding | E5: scripts/managers/factories/onboarding/oauth.py | F5: PY | G5: NET SEC | H5: oauth.py — shared, dependency-light Trakt OAuth helpers. ================================================================================ The device-code flow and token refresh used to live solely inside ``TraktInstanceManager``. They are extracted here so BOTH the onboarding wizard and the runtime manager use one implementation (DRY). These functions are pure HTTP — they take credentials and retu | I5: _log, auth_headers, fetch_username, refresh_token | P5: 266 | Q5: —
A6: 5 | B6: Entry · onboarding | C6: Cold start — first-run setup | D6: onboarding | E6: scripts/managers/factories/onboarding/prompts.py | F6: PY | G6: SEC | H6: prompts.py — input abstraction for interactive (TTY) and headless onboarding. ================================================================================ One ``Prompter`` interface, two implementations: * InteractivePrompter — terminal wizard. ``input()`` for normal fields, ``getpass`` for secrets (never echoed). Shows the current default in brackets; pressing Enter keeps it. Colour-coded, NO | I6: Prompter, InteractivePrompter, HeadlessPrompter · _c, red, yellow, green | P6: 235 | Q6: —
A7: 6 | B7: Entry · onboarding | C7: Cold start — first-run setup | D7: onboarding | E7: scripts/managers/factories/onboarding/schema.py | F7: PY | G7: NET DEL SEC | H7: schema.py — canonical config skeleton + shape builders for onboarding. ================================================================================ This mirrors the *LIVE* ``config.json`` shapes that the running readers actually consume — NOT the stale ``default_config.json`` / ``reference_keys.json`` (which still describe the old flat ``radarr-4k`` / flat ``tautulli`` layout). The shapes onbo | I7: empty_config, build_base_url, instance_block, deep_merge | P7: 233 | Q7: —
A8: 7 | B8: Entry · onboarding | C8: Cold start — first-run setup | D8: onboarding | E8: scripts/managers/factories/onboarding/validators.py | F8: PY | G8: NET SEC | H8: validators.py — live connectivity checks used during onboarding. ================================================================================ Warn-and-continue: every check returns a uniform dict and never raises, so a flaky service can never trap the user mid-setup. {"ok": bool, "version": str|None, "error": str|None, "root_folders": [str]} Sonarr/Radarr reuse the exact pattern from auth_vali | I8: _redact, _result, arr_status, _base | P8: 109 | Q8: —
A9: 8 | B9: Entry · onboarding | C9: Cold start — first-run setup | D9: onboarding | E9: scripts/managers/factories/onboarding/README.md | F9: MD | H9: OnboardingManager — - **File** — `scripts/managers/factories/onboarding/__init__.py` - **One-liner** — The first-run / full-setup wizard that interrogates the operator (interactively at a TTY or from `RECOMMENDARR_*` env vars headlessly) and writes a complete, secret-free `config.json` plus keyring-stored secrets before any service manager is built. | P9: 70
A10: 9 | B10: Entry · onboarding | C10: Cold start — first-run setup | D10: steps | E10: scripts/managers/factories/onboarding/steps/__init__.py | F10: PY | H10: steps/__init__.py — ordered onboarding step registry. ================================================================================ Order matters: Sonarr/Radarr run first so the Library step can offer the root folders discovered from those instances. The remaining services follow. | I10: build_steps, step_names | P10: 47 | Q10: —
A11: 10 | B11: Entry · onboarding | C11: Cold start — first-run setup | D11: steps | E11: scripts/managers/factories/onboarding/steps/arr.py | F11: PY | G11: NET SEC | H11: steps/arr.py — Sonarr & Radarr session collection. ================================================================================ Handles the user-defined number of sessions ("# of sessions for sonarr/radarr"). Interactive: asks how many sessions, then loops collecting host/port/api per session. Headless: ``RECOMMENDARR_<SERVICE>_INSTANCE_NAMES`` drives the loop and each field comes from ``RECOM | I11: ArrStep, SonarrStep, RadarrStep | P11: 154 | Q11: —
A12: 11 | B12: Entry · onboarding | C12: Cold start — first-run setup | D12: steps | E12: scripts/managers/factories/onboarding/steps/base.py | F12: PY | H12: steps/base.py — Step contract + small shared helpers. ================================================================================ Each step takes the live prompter, the working config dict, and a transient ``ctx`` (used to pass e.g. root folders discovered from Sonarr/Radarr to the Library step). A step returns a list of ``StepResult`` for the final summary. ``ctx`` is NEVER persisted — only | I12: StepResult, Step · should_configure, csv_field, host_field, token_expired | P12: 119 | Q12: —
A13: 12 | B13: Entry · onboarding | C13: Cold start — first-run setup | D13: steps | E13: scripts/managers/factories/onboarding/steps/daemons.py | F13: PY | H13: steps/daemons.py — background enrichment daemon (optional). ================================================================================ Asks whether to run the standalone Trakt enrichment daemon. When enabled, main.py (re)spawns ``scripts/support/daemons/enrich_daemon.py`` on each launch and the run itself becomes cache-only (no live Trakt calls → it can never hang on a 429). The daemon pre-f | I13: DaemonsStep | P13: 61 | Q13: —
A14: 13 | B14: Entry · onboarding | C14: Cold start — first-run setup | D14: steps | E14: scripts/managers/factories/onboarding/steps/extras.py | F14: PY | G14: SEC | H14: steps/extras.py — TVDB credentials (optional, store-only). ================================================================================ TVDB is collected but NOT live-validated here: it needs a separate login exchange to mint a token, which the runtime handles. Onboarding just stores the credentials (secrets → keyring). MAL has its own step (steps/mal.py) since it performs a real OAuth2/PKCE f | I14: TvdbStep | P14: 32 | Q14: —
A15: 14 | B15: Entry · onboarding | C15: Cold start — first-run setup | D15: steps | E15: scripts/managers/factories/onboarding/steps/library.py | F15: PY | H15: steps/library.py — root folders, genres, free-space limit, dry-run. ================================================================================ Runs after Sonarr/Radarr so it can offer the root folders discovered from those instances (stashed in ``ctx['root_folders']``) as choices. | I15: LibraryStep | P15: 61 | Q15: —
A16: 15 | B16: Entry · onboarding | C16: Cold start — first-run setup | D16: steps | E16: scripts/managers/factories/onboarding/steps/mal.py | F16: PY | G16: NET SEC | H16: steps/mal.py — MyAnimeList credentials + OAuth2 (PKCE) token generation. ================================================================================ MAL uses the OAuth2 authorization-code flow with PKCE (``code_challenge_method= plain``) — there is no device/poll flow like Trakt. So: * Interactive: print the authorize URL, the user approves in a browser and pastes back the redirected URL (or | I16: MalStep | P16: 130 | Q16: —
A17: 16 | B17: Entry · onboarding | C17: Cold start — first-run setup | D17: steps | E17: scripts/managers/factories/onboarding/steps/media.py | F17: PY | G17: NET SEC | H17: steps/media.py — Tautulli & Plex (optional, live-validated). ================================================================================ Tautulli is written in the LIVE nested shape ``{"default": {url, port, api, base_url}}`` (tautulli/__init__.py collapses ``.default``). Plex is a flat block. Both are optional: skipped via a yes/no prompt interactively, or skipped headless unless a value/pro | I17: TautulliStep, PlexStep · _tautulli_current | P17: 96 | Q17: —
A18: 17 | B18: Entry · onboarding | C18: Cold start — first-run setup | D18: steps | E18: scripts/managers/factories/onboarding/steps/nextep.py | F18: PY | H18: steps/nextep.py — next-episode (stay-ahead) prefetch tuning (recommended ON). ================================================================================ The Sonarr stay-ahead prefetch downloads upcoming episodes so the next one is ready before you press play. Three tunables shape HOW FAR it walks per series — all recommended ON and live under ``acquisition.next_episode``: * graduated_cap — s | I18: NextEpisodeStep | P18: 201 | Q18: —
A19: 18 | B19: Entry · onboarding | C19: Cold start — first-run setup | D19: steps | E19: scripts/managers/factories/onboarding/steps/notifications.py | F19: PY | G19: NET SEC | H19: steps/notifications.py — Discord notifications (optional). ================================================================================ ``notifications.discord.webhook_url`` is a secret (matched by the "webhook" substring in is_secret_key), so it is stored in the keyring like any other. | I19: NotificationsStep | P19: 36 | Q19: —
A20: 19 | B20: Entry · onboarding | C20: Cold start — first-run setup | D20: steps | E20: scripts/managers/factories/onboarding/steps/test_nextep_step.py | F20: PY | H20: Tests for the NextEpisodeStep onboarding step — the three modes (recommended / customize / off) write the expected acquisition.next_episode block. | I20: _FakePrompter · _run, _all_notices, test_recommended_writes_the_default_blocks, test_off_writes_enabled_false_blocks_to_disable | P20: 175 | Q20: —
A21: 20 | B21: Entry · onboarding | C21: Cold start — first-run setup | D21: steps | E21: scripts/managers/factories/onboarding/steps/trakt.py | F21: PY | G21: NET SEC | H21: steps/trakt.py — Trakt credentials + OAuth token generation. ================================================================================ Collects client_id/client_secret, then generates the OAuth token via the shared ``oauth`` helper: refresh an existing token if a refresh_token is present, otherwise run the device-code flow (works on a TTY and headless — the device code is surfaced through t | I21: TraktStep | P21: 70 | Q21: —
A22: 21 | B22: Entry · config + secrets | C22: Cold start — config load | D22: config | E22: scripts/managers/factories/config/__Init__.py | F22: PY | G22: SEC | I22: ConfigManager | P22: 55 | Q22: —
A23: 22 | B23: Entry · config + secrets | C23: Cold start — config load | D23: config | E23: scripts/managers/factories/config/config_cli.py | F23: PY | I23: ConfigCLI | P23: 51 | Q23: —
A24: 23 | B24: Entry · config + secrets | C24: Cold start — config load | D24: config | E24: scripts/managers/factories/config/config_constants.py | F24: PY | G24: SEC | I24: SensitiveKeys, ConfigGroups | P24: 15 | Q24: —
A25: 24 | B25: Entry · config + secrets | C25: Cold start — config load | D25: config | E25: scripts/managers/factories/config/config_loader.py | F25: PY | G25: DEL SEC FS | I25: ConfigLoader | P25: 140 | Q25: —
A26: 25 | B26: Entry · config + secrets | C26: Cold start — config load | D26: config | E26: scripts/managers/factories/config/config_resolver.py | F26: PY | I26: ConfigResolver | P26: 13 | Q26: —
A27: 26 | B27: Entry · config + secrets | C27: Cold start — config load | D27: config | E27: scripts/managers/factories/config/config_sanitizer.py | F27: PY | I27: ConfigSanitizer | P27: 24 | Q27: —
A28: 27 | B28: Entry · config + secrets | C28: Cold start — config load | D28: config | E28: scripts/managers/factories/config/secret_bootstrap.py | F28: PY | G28: SEC | H28: SecretBootstrap — first-run / reinstall detection + setup for the SecretStore. ================================================================================ On startup it AUDITS every secret the config expects and reports where each one resolves from: env → RECOMMENDARR_* environment variable (production / containers) keyring → OS keyring (Windows Credential Manager / Keychain / Secret Service) | I28: SecretBootstrap | P28: 139 | Q28: —
A29: 28 | B29: Entry · config + secrets | C29: Cold start — config load | D29: config | E29: scripts/managers/factories/config/secret_store.py | F29: PY | G29: NET SEC | H29: SecretStore — keeps API keys / tokens out of plaintext ``config.json``. ================================================================================ Resolution order for a secret (first hit wins): 1. Environment variable ``RECOMMENDARR_<PATH>`` 12-factor / production: inject via Docker secrets, k8s, CI, or a cloud secret manager. e.g. trakt.client_secret -> RECOMMENDARR_TRAKT_CLIENT_SECRET 2. | I29: SecretStore · is_secret_key, env_name, iter_secret_paths | P29: 155 | Q29: —
A30: 29 | B30: Entry · config + secrets | C30: Cold start — config load | D30: config | E30: scripts/managers/factories/config/validator.py | F30: PY | G30: NET SEC | I30: ConfigValidator | P30: 125 | Q30: —
A31: 30 | B31: Entry · config + secrets | C31: Cold start — config load | D31: config | E31: scripts/managers/factories/config/README.md | F31: MD | H31: ConfigManager — **File** — `scripts/managers/factories/config/__Init__.py` **One-liner** — The process-wide configuration object: it loads `config.json` (overlaying secrets from the OS keyring / env vars), exposes typed getters/setters, and persists changes back to disk with secrets stripped out. | P31: 75
A32: 31 | B32: Entry · auth validation | C32: Cold start — parallel auth check | D32: auth | E32: scripts/support/utilities/auth_validator.py | F32: PY | G32: NET SEC | H32: ServiceAuthValidator ==================== Validates Radarr, Sonarr, and Trakt credentials concurrently and emits a single summary line: [Auth] ✅ Radarr:standard v6.1 ✅ Sonarr:720 v4.0 ✅ Trakt:{username} (0.84s) Individual service log lines are suppressed during the auth check. Called from Main.__init__ before any manager is constructed. | I32: validate_all, _check_radarr, _check_sonarr, _check_trakt | P32: 174 | Q32: —
A33: 32 | B33: Entry · auth validation | C33: Cold start — parallel auth check | D33: auth | E33: scripts/support/utilities/bootstrap.py | F33: PY | P33: 2 | Q33: —
A34: 33 | B34: Entry · logging | C34: Cold start — logger | D34: logger | E34: scripts/support/utilities/logger/formatters.py | F34: PY | I34: JsonFormatter | P34: 17 | Q34: —
A35: 34 | B35: Entry · logging | C35: Cold start — logger | D35: logger | E35: scripts/support/utilities/logger/logger.py | F35: PY | G35: NET DEL SEC FS | I35: _ColorFormatter, LoggerManager · _supports_color, _strip_decor, get_logger | P35: 507 | Q35: —
A36: 35 | B36: Entry · setup scripts | C36: Cold start — provisioning helpers | D36: setup | E36: scripts/support/setup/install_hooks.py | F36: PY | G36: EXEC SEC | H36: install_hooks.py - activate the committed git hooks (pre-commit secret guard). python scripts/support/setup/install_hooks.py Points git at the repo's committed hooks (scripts/hooks) via core.hooksPath, so the pre-commit secret scanner runs on every commit in this clone. Run once per clone. (Optional but recommended: install `gitleaks` for the full ruleset - the hook uses it automatically when pres | I36: _red, _green, main | P36: 47 | Q36: — | R36: ▶
A37: 36 | B37: Entry · setup scripts | C37: Cold start — provisioning helpers | D37: setup | E37: scripts/support/setup/migrate_secrets.py | F37: PY | G37: SEC | H37: migrate_secrets.py - move plaintext secrets out of config.json into the OS keyring. Run once, e.g. right after rotating credentials: python scripts/support/setup/migrate_secrets.py It reads scripts/support/config/config.json, stores every secret value in the OS keyring (Windows Credential Manager / macOS Keychain / Linux Secret Service), and rewrites config.json with those fields BLANK. Downstream | I37: _red, _yellow, _green, _inline_secrets | P37: 88 | Q37: — | R37: ▶
A38: 37 | B38: Entry · setup scripts | C38: Cold start — provisioning helpers | D38: setup | E38: scripts/support/setup/onboarding.py | F38: PY | G38: SEC | H38: onboarding.py - guided first-run / full setup for Recommendarr. python scripts/support/setup/onboarding.py # interactive wizard (auto-detects TTY) python scripts/support/setup/onboarding.py --headless # env-driven (CI / Docker / unraid) python scripts/support/setup/onboarding.py --reconfigure # re-run every step, pre-filled python scripts/support/setup/onboarding.py --service trakt # re-run just o | I38: main | P38: 85 | Q38: — | R38: ▶
A39: 38 | B39: Entry · setup scripts | C39: Cold start — provisioning helpers | D39: setup | E39: scripts/support/setup/setup_secrets.py | F39: PY | G39: SEC | H39: setup_secrets.py - interactive SecretStore setup / update. python scripts/support/setup/setup_secrets.py Shows where each secret currently resolves from (env / keyring / plaintext / missing), then lets you set or update each one with hidden input. Values are stored in the OS keyring; config.json secret fields are left blank. Press Enter to keep the current value. Use this for first-time setup, aft | I39: _red, _yellow, _green, main | P39: 88 | Q39: — | R39: ▶
A40: 39 | B40: Entry · git/CI hooks | C40: Dev-time — pre-commit guards | D40: hooks | E40: scripts/hooks/brain_purity.py | F40: PY | G40: NET FS | H40: Brain-layer purity guard for Recommendarr (ML migration invariant). ``machine_learning/`` is the pure decision/brain layer: it THINKS, the service managers FETCH / CACHE / APPLY. To keep that boundary from eroding as new decision cores land, every module under the migrated brain subpackages must NOT import: * an HTTP client (requests / httpx / urllib3 / aiohttp) * the service layer (scripts.manage | I40: _violations, main | P40: 99 | Q40: — | R40: ▶
...
